Workbook

Sheet Retirement Goal Planner
A1: FINANCIAL GOAL PLANNER — RETIREMENT CORPUS WITH VARIABLE ASSET ALLOCATION
A2: Enter your numbers only in the YELLOW cells (blue text). Every other cell recalculates automatically.
A4: 1. Retirement Expense Estimation & Corpus Required
A5: 1 | B5: Current monthly expenses that will persist in retirement (₹) | F5: 60000
A6: 2 | B6: Annual expenses that will persist in retirement (₹) | F6: 100000
A7: 3 | B7: Total average monthly expenses (annual / 12) | F7: =F5+F6/12
A8: 4 | B8: Inflation before retirement (%) | F8: 6
A9: 5 | B9: Current age (years) | F9: 35
A10: 6 | B10: Age you wish to retire (years) | F10: 60
A11: 7 | B11: No. of years you expect to live (life expectancy, age) | F11: 85
A12: 8 | B12: Years to retirement | F12: =F10-F9
A13: 9 | B13: Monthly expenses in first year of retirement | F13: =F7*(1+F8/100)^F12
A14: 10 | B14: Years in retirement | F14: =F11-F10
A15: 11 | B15: Inflation during retirement (%) | F15: 5
A16: 12 | B16: Post-tax average return from retirement corpus (%) | F16: 6
B17: Note: keep this at a conservative/low number — it is the return earned on the corpus AFTER you retire.
A18: 13 | B18: TOTAL CORPUS REQUIRED AT RETIREMENT | F18: =IF(F16=F15,F13*12*F14/(1+F16/100),F13*12*(1-((1+F15/100)/(1+F16/100))^F14)/((F16-F15)/100))
A20: 2. Post-Tax Return Assumptions (for current & future investments)
A21: 14 | B21: Post-tax return expected from equity investments (%) | F21: 10
A22: 15 | B22: Post-tax return expected from current taxable fixed income (%) | F22: 6
B23: Note: FD, debt fund, etc.
A24: 16 | B24: Rate of return expected from current tax-free fixed income (%) | F24: 7
B25: Note: EPF + PPF + LIC
A27: 3. Present Value of Investments → Future Value at Retirement
B28: Particulars | F28: Present Value (₹) | G28: Future Value at Retirement (₹)
A29: 17 | B29: Value of current equity investments | F29: 500000 | G29: =F29*(1+F21/100)^F12
A30: 18 | B30: Value of current taxable fixed income investments | F30: 300000 | G30: =F30*(1+F22/100)^F12
A31: 19 | B31: Value of current tax-free fixed income investments | F31: 300000 | G31: =F31*(1+F24/100)^F12
A32: 20 | B32: Lump sum benefits expected at retirement (gratuity, etc.) | F32: 200000 | G32: =F32
A33: 21 | B33: Current monthly mandatory EPF contribution (employer + employee) | F33: 12000 | G33: =IF(F35=F34,F33*12*F12*(1+F35/100)^(F12-1),F33*12*((1+F35/100)^F12-(1+F34/100)^F12)/((F35-F34)/100))
A34: 22 | B34: Annual increase in this contribution (%) | F34: 8
A35: 23 | B35: Expected rate of return for EPF / NPS (%) | F35: 8
B37: TOTAL FUTURE VALUE OF EXISTING INVESTMENTS | G37: =G29+G30+G31+G32+G33
A39: NET CORPUS TO BE ACCUMULATED (Total Corpus Required − Total Future Value of Investments) | G39: =F18-G37

Sheet Budgeting Tool
A1: Objective of this budget tool | D1: NEW Planning done at the beginning of the month (both income and expenses)
A2: 1. To keep an eye on the income from various sources and expenses -- MOM basis
A3: 2. To see the PFTM and AFTM, and differences | D3: NEW Provision to keep storage of the monthly Plan versus Actual status for a few years
A4: 3. Tracking on daily basis and the summation also daily basis
A5: 4. Totalling the daily data for each week and summation as on date
A6: 5. Linked to Goals
A7: MY ASSETZ | PERSONAL FINANCIAL BUDGET & CASH FLOW PLANNER
A8: Budget for the month of ____________________
A9: Income heads | B9: Plan | C9: Actual income | J9: Plan Minus Actual
D10: Week 1 | E10: Week 2 | F10: Week 3 | G10: Week 4 | H10: Week 5 | I10: Month total | J10: Plan Minus Actual
A11: Salary | I11: =SUM(D11:H11) | J11: =B11-I11
A12: Rental | I12: =SUM(D12:H12) | J12: =B12-I12
A13: Business | I13: =SUM(D13:H13) | J13: =B13-I13
A14: Capital gain | I14: =SUM(D14:H14) | J14: =B14-I14
A15: Others | I15: =SUM(D15:H15) | J15: =B15-I15
A16: Total | B16: =SUM(B11:B15) | C16: =SUM(C11:C15) | D16: =SUM(D11:D15) | E16: =SUM(E11:E15) | F16: =SUM(F11:F15) | G16: =SUM(G11:G15) | H16: =SUM(H11:H15) | I16: =SUM(I11:I15) | J16: =SUM(J11:J15)
A17: Expenses
A18: Heads | B18: Sub heads | C18: Plan | D18: Week 1 | E18: Week 2 | F18: Week 3 | G18: Week 4 | H18: Week 5 | I18: Month total | J18: Savings / overspent
A19: Housing | B19: Rent | I19: =SUM(D19:H19) | J19: =C19-I19
B20: Second mortgage or rent | I20: =SUM(D20:H20) | J20: =C20-I20
B21: Electricity | I21: =SUM(D21:H21) | J21: =C21-I21
B22: Gas | I22: =SUM(D22:H22) | J22: =C22-I22
B23: Water and sewer | I23: =SUM(D23:H23) | J23: =C23-I23
B24: House and Water | I24: =SUM(D24:H24) | J24: =C24-I24
B25: Waste removal | I25: =SUM(D25:H25) | J25: =C25-I25
B26: Maintenance or repairs | I26: =SUM(D26:H26) | J26: =C26-I26
B27: Servant / maid | I27: =SUM(D27:H27) | J27: =C27-I27
B28: Monthly maintenance | I28: =SUM(D28:H28) | J28: =C28-I28
B29: Gardening | I29: =SUM(D29:H29) | J29: =C29-I29
B30: Total | C30: =SUM(C19:C29) | D30: =SUM(D19:D29) | E30: =SUM(E19:E29) | F30: =SUM(F19:F29) | G30: =SUM(G19:G29) | H30: =SUM(H19:H29) | I30: =SUM(I19:I29) | J30: =SUM(J19:J29)
A31: Food | B31: Groceries | I31: =SUM(D31:H31) | J31: =C31-I31
B32: Dining out | I32: =SUM(D32:H32) | J32: =C32-I32
B33: Vegetables / fruits | I33: =SUM(D33:H33) | J33: =C33-I33
B34: Snacks etc | I34: =SUM(D34:H34) | J34: =C34-I34
B35: Meat etc | I35: =SUM(D35:H35) | J35: =C35-I35
B36: Total | C36: =SUM(C31:C35) | D36: =SUM(D31:D35) | E36: =SUM(E31:E35) | F36: =SUM(F31:F35) | G36: =SUM(G31:G35) | H36: =SUM(H31:H35) | I36: =SUM(I31:I35) | J36: =SUM(J31:J35)
A37: Children | B37: Medical | I37: =SUM(D37:H37) | J37: =C37-I37
B38: Clothing children related only | I38: =SUM(D38:H38) | J38: =C38-I38
B39: Evening tuition expenses | I39: =SUM(D39:H39) | J39: =C39-I39
B40: School tuition | I40: =SUM(D40:H40) | J40: =C40-I40
...

Sheet Financial Plan Progress
A1: MY ASSETZ
A2: Your Financial Plan Progress Report
A4: Time Horizon | B4: Goal | C4: Priority of Goals | D4: Time Horizon | E4: Totally Required Investment | F4: Investments Already Made | G4: Balance / Monthly Investment Need | H4: Achievable or Not
A5: Very short term investment requirement | B5: Buying a Honda City | D5: < 1 year | G5: =IF(OR(E5="",F5=""),"",E5-F5) | H5: =IF(G5="","Enter values",IF(G5<=0,"Review","To be assessed"))
A6: Short term investment requirement | D6: 1 - 3 years | G6: =IF(OR(E6="",F6=""),"",E6-F6) | H6: =IF(G6="","Enter values",IF(G6<=0,"Review","To be assessed"))
A7: Medium term investment requirement | D7: 3 - 5 years | G7: =IF(OR(E7="",F7=""),"",E7-F7) | H7: =IF(G7="","Enter values",IF(G7<=0,"Review","To be assessed"))
A8: Intermediate term investment | B8: Son's education | D8: 5 - 10 years | G8: =IF(OR(E8="",F8=""),"",E8-F8) | H8: =IF(G8="","Enter values",IF(G8<=0,"Review","To be assessed"))
A9: Long term investment requirement | B9: Retirement | D9: > 10 years | G9: =IF(OR(E9="",F9=""),"",E9-F9) | H9: =IF(G9="","Enter values",IF(G9<=0,"Review","To be assessed"))
A12: Please see comments provided in the cells

Sheet Dashboard
A1: MY ASSETZ
A2: Monthly Financial Dashboard
A4: Total Income - Actual | B4: ='Budgeting Tool'!I16
A5: Total Expenses - Actual | B5: ='Budgeting Tool'!I144
A6: Net Cash Flow | B6: ='Budgeting Tool'!C146
A9: Expense Category | B9: Actual
A10: Housing | B10: ='Budgeting Tool'!I30
A11: Food | B11: ='Budgeting Tool'!I36
A12: Children | B12: ='Budgeting Tool'!I49
A13: Communication | B13: ='Budgeting Tool'!I56
A14: Transportation | B14: ='Budgeting Tool'!I65
A15: Entertainment | B15: ='Budgeting Tool'!I74
A16: Supports to dependents | B16: ='Budgeting Tool'!I78
A17: Personal Care | B17: ='Budgeting Tool'!I86
A18: Replacement expenses | B18: ='Budgeting Tool'!I93
A19: Taxes - all | B19: ='Budgeting Tool'!I102
A20: Savings or Investments | B20: ='Budgeting Tool'!I112
A21: Loans repayment | B21: ='Budgeting Tool'!I123
A22: Insurance | B22: ='Budgeting Tool'!I129
A23: Personal | B23: ='Budgeting Tool'!I135
A24: Charity | B24: ='Budgeting Tool'!I139
A25: Others | B25: ='Budgeting Tool'!I143
